<?xml version="1.0"?>
<robot name="my_robot">
    
    <material name="green">
        <color rgba="0 0.5 0 1"></color>
    </material>
    <material name="blue">
        <color rgba="0 0 0.5 1"></color>
    </material>
    <material name="grey">
        <color rgba="0.5 0.5 0.5 1"></color>
    </material>

    <link name="base_link">
        <visual>
            <geometry>
                <box size="0.6 0.4 0.2" />
            </geometry>
            <origin xyz="0 0 0.1" rpy="0 0 0"></origin>
            <material name="blue"></material>
        </visual>
    </link>

    <link name="second_link">
        <visual>
            <geometry>
                <cylinder radius="0.1" length="0.2"></cylinder>
            </geometry>
            <origin xyz="0 0 0.1" rpy="0 0 0"></origin>
            <material name="grey"></material>
        </visual>
    </link>

    <link name="third_link">
        <visual>
            <geometry>
                <box size="0.1 0.2 0.1" />
            </geometry>
            <origin xyz="0 0 0.05" rpy="0 0 0"></origin>
            <material name="blue"></material>
        </visual>
    </link>


    <joint name="base_second_joint" type="revolute">
        <parent link="base_link" />
        <child link="second_link" />
        <origin xyz="0 0 0.2" rpy="0 0 0" />
        <axis xyz="0 0 1" />
        <limit lower="-1.57" upper="1.57" velocity="100" effort="100" />
    </joint>

    <joint name="second_third_joint" type="prismatic">
        <parent link="second_link" />
        <child link="third_link" />
        <origin xyz="0 0 0.2" rpy="0 0 0" />
        <axis xyz="1 0 0" />
        <limit lower="0.0" upper="0.5" velocity="100" effort="100" />
    </joint>

</robot>
